Workbook

Sheet Sheet1
A1: Date | B1: HOLD+Galaxis+EURO+Abszolút+Hozamú+Alapok+Alapja | C1: HOLD+Hozamkereső+Európai+Származtatott+Részvény+Befektetési+Alap | D1: HOLD+Kötvény+Befektetési+Alap | E1: HOLD+Közép-európai+Részvény+Befektetési+Alap | F1: HOLD+Nemzetközi+Részvény+Alapok+Alapja+A+sorozat | G1: HOLD+Orion+Abszolút+Hozamú+Származtatott+Befektetési+Alap+B+sorozat+EUR | H1: HOLD+Részvény+Befektetési+Alap+A+sorozat+HUF | I1: HOLD+Részvény+Befektetési+Alap+B+sorozat+EUR | J1: HOLD+Rövid+Futamidejű+Kötvény+Befektetési+Alap | K1: HOLD+Széf+USD+Abszolút+Hozamú+Befektetési+Alap | L1: HOLD+VM+Abszolút+Hozamú+Származtatott+Befektetési+Alap+C+sorozat | M1: HOLD+VM+EURO+Abszolút+Hozamú+Alapok+Alapja | N1: Palomar+Abszolút+Hozamú+Származtatott+Befektetési+Alap+A+sorozat+HUF | O1: Palomar+Abszolút+Hozamú+Származtatott+Befektetési+Alap+B+sorozat+EUR | P1: Palomar+Abszolút+Hozamú+Származtatott+Befektetési+Alap+C+sorozat+USD | Q1: Platina+Delta+Abszolút+Hozamú+Származtatott+Befektetési+Alap+E+sorozat+EUR | R1: Platina+Delta+Abszolút+Hozamú+Származtatott+Befektetési+Alap+X+sorozat+HUF | S1: Superposition+Abszolút+Hozamú+Származtatott+Befektetési+Alap+A+sorozat | T1: Superposition+Abszolút+Hozamú+Származtatott+Befektetési+Alap+D+sorozat+EUR
A2: 35926 | J2: 1
A3: 35927 | J3: 1
A4: 35928 | J4: 1.002716
A5: 35929 | J5: 1.002638
A6: 35930 | J6: 1.002466
A7: 35931 | J7: 1.002466
A8: 35932 | J8: 1.002466
A9: 35933 | J9: 1.002869
A10: 35934 | J10: 1.004079
A11: 35935 | J11: 1.004665
A12: 35936 | J12: 1.005081
A13: 35937 | J13: 1.010888
... A1026: 36978 | J1026: 1.457111
A1027: 36979 | D1027: 1.001794 | H1027: 1.001413 | J1027: 1.453654
A1028: 36980 | D1028: 1.001979 | H1028: 1.001663 | J1028: 1.457943
A1029: 36983 | D1029: 1.002493 | H1029: 1.001849 | J1029: 1.455817
A1030: 36984 | D1030: 1.002681 | H1030: 1.002212 | J1030: 1.458662
A1031: 36985 | D1031: 1.002863 | H1031: 1.0023 | J1031: 1.45856
A1032: 36986 | D1032: 1.003211 | H1032: 1.002523 | J1032: 1.460669
A1033: 36987 | D1033: 1.003536 | H1033: 1.002583 | J1033: 1.459115
A1034: 36990 | D1034: 1.003827 | H1034: 0.999086 | J1034: 1.457171
A1035: 36991 | D1035: 1.004145 | H1035: 1.001687 | J1035: 1.462285
A1036: 36992 | D1036: 1.004386 | H1036: 1.011887 | J1036: 1.459051
A1037: 36993 | D1037: 1.00472 | H1037: 1.017349 | J1037: 1.458356
A1038: 36994 | D1038: 1.004828 | H1038: 1.018333 | J1038: 1.459734
... A1363: 37468 | D1363: 1.124561 | H1363: 1.181621 | J1363: 1.624237
A1364: 37469 | D1364: 1.124044 | F1364: 1.001163 | H1364: 1.185056 | J1364: 1.623272
A1365: 37470 | D1365: 1.12392 | F1365: 0.982965 | H1365: 1.187116 | J1365: 1.624448
A1366: 37473 | D1366: 1.124495 | F1366: 0.941676 | H1366: 1.178882 | J1366: 1.622188
A1367: 37474 | D1367: 1.124894 | F1367: 0.989298 | H1367: 1.18572 | J1367: 1.624715
A1368: 37475 | D1368: 1.124662 | F1368: 1.003194 | H1368: 1.178671 | J1368: 1.622788
A1369: 37476 | D1369: 1.125251 | F1369: 1.020912 | H1369: 1.180008 | J1369: 1.622688
A1370: 37477 | D1370: 1.126555 | F1370: 1.025546 | H1370: 1.177691 | J1370: 1.625752
A1371: 37480 | D1371: 1.128428 | F1371: 1.017426 | H1371: 1.180343 | J1371: 1.630437
A1372: 37481 | D1372: 1.12808 | F1372: 1.001705 | H1372: 1.180573 | J1372: 1.625263
A1373: 37482 | D1373: 1.127494 | F1373: 1.020829 | H1373: 1.182077 | J1373: 1.626857
A1374: 37483 | D1374: 1.127286 | F1374: 1.041252 | H1374: 1.196809 | J1374: 1.63287
A1375: 37484 | D1375: 1.125877 | F1375: 1.040723 | H1375: 1.192467 | J1375: 1.630371
... A2681: 39380 | D2681: 1.646861 | F2681: 1.333157 | H2681: 4.553374 | J2681: 2.364595
...

Sheet derivalt
A1: Date | B1: HOLD+Galaxis+EURO+Abszolút+Hozamú+Alapok+Alapja | C1: HOLD+Hozamkereső+Európai+Származtatott+Részvény+Befektetési+Alap | D1: HOLD+Kötvény+Befektetési+Alap | E1: HOLD+Közép-európai+Részvény+Befektetési+Alap | F1: HOLD+Nemzetközi+Részvény+Alapok+Alapja+A+sorozat | G1: HOLD+Orion+Abszolút+Hozamú+Származtatott+Befektetési+Alap+B+sorozat+EUR | H1: HOLD+Részvény+Befektetési+Alap+A+sorozat+HUF | I1: HOLD+Részvény+Befektetési+Alap+B+sorozat+EUR | J1: HOLD+Rövid+Futamidejű+Kötvény+Befektetési+Alap | K1: HOLD+Széf+USD+Abszolút+Hozamú+Befektetési+Alap | L1: HOLD+VM+Abszolút+Hozamú+Származtatott+Befektetési+Alap+C+sorozat | M1: HOLD+VM+EURO+Abszolút+Hozamú+Alapok+Alapja | N1: Palomar+Abszolút+Hozamú+Származtatott+Befektetési+Alap+A+sorozat+HUF | O1: Palomar+Abszolút+Hozamú+Származtatott+Befektetési+Alap+B+sorozat+EUR | P1: Palomar+Abszolút+Hozamú+Származtatott+Befektetési+Alap+C+sorozat+USD | Q1: Platina+Delta+Abszolút+Hozamú+Származtatott+Befektetési+Alap+E+sorozat+EUR | R1: Platina+Delta+Abszolút+Hozamú+Származtatott+Befektetési+Alap+X+sorozat+HUF | S1: Superposition+Abszolút+Hozamú+Származtatott+Befektetési+Alap+A+sorozat | T1: Superposition+Abszolút+Hozamú+Származtatott+Befektetési+Alap+D+sorozat+EUR
A2: 35926 | B2: =(Sheet1!B4-Sheet1!B2)/($A$4-$A$2) -> 0 | C2: =(Sheet1!C4-Sheet1!C2)/($A$4-$A$2) -> 0 | D2: =(Sheet1!D4-Sheet1!D2)/($A$4-$A$2) -> 0 | E2: =(Sheet1!E4-Sheet1!E2)/($A$4-$A$2) -> 0 | F2: =(Sheet1!F4-Sheet1!F2)/($A$4-$A$2) -> 0 | G2: =(Sheet1!G4-Sheet1!G2)/($A$4-$A$2) -> 0 | H2: =(Sheet1!H4-Sheet1!H2)/($A$4-$A$2) -> 0 | I2: =(Sheet1!I4-Sheet1!I2)/($A$4-$A$2) -> 0 | ... T2: =(Sheet1!T4-Sheet1!T2)/($A$4-$A$2) -> 0
A3: 35927 | B3: =(Sheet1!B5-Sheet1!B3)/($A$4-$A$2) -> 0 | C3: =(Sheet1!C5-Sheet1!C3)/($A$4-$A$2) -> 0 | D3: =(Sheet1!D5-Sheet1!D3)/($A$4-$A$2) -> 0 | E3: =(Sheet1!E5-Sheet1!E3)/($A$4-$A$2) -> 0 | F3: =(Sheet1!F5-Sheet1!F3)/($A$4-$A$2) -> 0 | G3: =(Sheet1!G5-Sheet1!G3)/($A$4-$A$2) -> 0 | H3: =(Sheet1!H5-Sheet1!H3)/($A$4-$A$2) -> 0 | I3: =(Sheet1!I5-Sheet1!I3)/($A$4-$A$2) -> 0 | ... T3: =(Sheet1!T5-Sheet1!T3)/($A$4-$A$2) -> 0
A4: 35928 | B4: =(Sheet1!B6-Sheet1!B4)/($A$4-$A$2) -> 0 | C4: =(Sheet1!C6-Sheet1!C4)/($A$4-$A$2) -> 0 | D4: =(Sheet1!D6-Sheet1!D4)/($A$4-$A$2) -> 0 | E4: =(Sheet1!E6-Sheet1!E4)/($A$4-$A$2) -> 0 | F4: =(Sheet1!F6-Sheet1!F4)/($A$4-$A$2) -> 0 | G4: =(Sheet1!G6-Sheet1!G4)/($A$4-$A$2) -> 0 | H4: =(Sheet1!H6-Sheet1!H4)/($A$4-$A$2) -> 0 | I4: =(Sheet1!I6-Sheet1!I4)/($A$4-$A$2) -> 0 | ... T4: =(Sheet1!T6-Sheet1!T4)/($A$4-$A$2) -> 0
A5: 35929 | B5: =(Sheet1!B7-Sheet1!B5)/($A$4-$A$2) -> 0 | C5: =(Sheet1!C7-Sheet1!C5)/($A$4-$A$2) -> 0 | D5: =(Sheet1!D7-Sheet1!D5)/($A$4-$A$2) -> 0 | E5: =(Sheet1!E7-Sheet1!E5)/($A$4-$A$2) -> 0 | F5: =(Sheet1!F7-Sheet1!F5)/($A$4-$A$2) -> 0 | G5: =(Sheet1!G7-Sheet1!G5)/($A$4-$A$2) -> 0 | H5: =(Sheet1!H7-Sheet1!H5)/($A$4-$A$2) -> 0 | I5: =(Sheet1!I7-Sheet1!I5)/($A$4-$A$2) -> 0 | ... T5: =(Sheet1!T7-Sheet1!T5)/($A$4-$A$2) -> 0
A6: 35930 | B6: =(Sheet1!B8-Sheet1!B6)/($A$4-$A$2) -> 0 | C6: =(Sheet1!C8-Sheet1!C6)/($A$4-$A$2) -> 0 | D6: =(Sheet1!D8-Sheet1!D6)/($A$4-$A$2) -> 0 | E6: =(Sheet1!E8-Sheet1!E6)/($A$4-$A$2) -> 0 | F6: =(Sheet1!F8-Sheet1!F6)/($A$4-$A$2) -> 0 | G6: =(Sheet1!G8-Sheet1!G6)/($A$4-$A$2) -> 0 | H6: =(Sheet1!H8-Sheet1!H6)/($A$4-$A$2) -> 0 | I6: =(Sheet1!I8-Sheet1!I6)/($A$4-$A$2) -> 0 | ... T6: =(Sheet1!T8-Sheet1!T6)/($A$4-$A$2) -> 0
A7: 35931 | B7: =(Sheet1!B9-Sheet1!B7)/($A$4-$A$2) -> 0 | C7: =(Sheet1!C9-Sheet1!C7)/($A$4-$A$2) -> 0 | D7: =(Sheet1!D9-Sheet1!D7)/($A$4-$A$2) -> 0 | E7: =(Sheet1!E9-Sheet1!E7)/($A$4-$A$2) -> 0 | F7: =(Sheet1!F9-Sheet1!F7)/($A$4-$A$2) -> 0 | G7: =(Sheet1!G9-Sheet1!G7)/($A$4-$A$2) -> 0 | H7: =(Sheet1!H9-Sheet1!H7)/($A$4-$A$2) -> 0 | I7: =(Sheet1!I9-Sheet1!I7)/($A$4-$A$2) -> 0 | ... T7: =(Sheet1!T9-Sheet1!T7)/($A$4-$A$2) -> 0
A8: 35932 | B8: =(Sheet1!B10-Sheet1!B8)/($A$4-$A$2) -> 0 | C8: =(Sheet1!C10-Sheet1!C8)/($A$4-$A$2) -> 0 | D8: =(Sheet1!D10-Sheet1!D8)/($A$4-$A$2) -> 0 | E8: =(Sheet1!E10-Sheet1!E8)/($A$4-$A$2) -> 0 | F8: =(Sheet1!F10-Sheet1!F8)/($A$4-$A$2) -> 0 | G8: =(Sheet1!G10-Sheet1!G8)/($A$4-$A$2) -> 0 | H8: =(Sheet1!H10-Sheet1!H8)/($A$4-$A$2) -> 0 | I8: =(Sheet1!I10-Sheet1!I8)/($A$4-$A$2) -> 0 | ... T8: =(Sheet1!T10-Sheet1!T8)/($A$4-$A$2) -> 0
A9: 35933 | B9: =(Sheet1!B11-Sheet1!B9)/($A$4-$A$2) -> 0 | C9: =(Sheet1!C11-Sheet1!C9)/($A$4-$A$2) -> 0 | D9: =(Sheet1!D11-Sheet1!D9)/($A$4-$A$2) -> 0 | E9: =(Sheet1!E11-Sheet1!E9)/($A$4-$A$2) -> 0 | F9: =(Sheet1!F11-Sheet1!F9)/($A$4-$A$2) -> 0 | G9: =(Sheet1!G11-Sheet1!G9)/($A$4-$A$2) -> 0 | H9: =(Sheet1!H11-Sheet1!H9)/($A$4-$A$2) -> 0 | I9: =(Sheet1!I11-Sheet1!I9)/($A$4-$A$2) -> 0 | ... T9: =(Sheet1!T11-Sheet1!T9)/($A$4-$A$2) -> 0
A10: 35934 | B10: =(Sheet1!B12-Sheet1!B10)/($A$4-$A$2) -> 0 | C10: =(Sheet1!C12-Sheet1!C10)/($A$4-$A$2) -> 0 | D10: =(Sheet1!D12-Sheet1!D10)/($A$4-$A$2) -> 0 | E10: =(Sheet1!E12-Sheet1!E10)/($A$4-$A$2) -> 0 | F10: =(Sheet1!F12-Sheet1!F10)/($A$4-$A$2) -> 0 | G10: =(Sheet1!G12-Sheet1!G10)/($A$4-$A$2) -> 0 | H10: =(Sheet1!H12-Sheet1!H10)/($A$4-$A$2) -> 0 | I10: =(Sheet1!I12-Sheet1!I10)/($A$4-$A$2) -> 0 | ... T10: =(Sheet1!T12-Sheet1!T10)/($A$4-$A$2) -> 0
A11: 35935 | B11: =(Sheet1!B13-Sheet1!B11)/($A$4-$A$2) -> 0 | C11: =(Sheet1!C13-Sheet1!C11)/($A$4-$A$2) -> 0 | D11: =(Sheet1!D13-Sheet1!D11)/($A$4-$A$2) -> 0 | E11: =(Sheet1!E13-Sheet1!E11)/($A$4-$A$2) -> 0 | F11: =(Sheet1!F13-Sheet1!F11)/($A$4-$A$2) -> 0 | G11: =(Sheet1!G13-Sheet1!G11)/($A$4-$A$2) -> 0 | H11: =(Sheet1!H13-Sheet1!H11)/($A$4-$A$2) -> 0 | I11: =(Sheet1!I13-Sheet1!I11)/($A$4-$A$2) -> 0 | ... T11: =(Sheet1!T13-Sheet1!T11)/($A$4-$A$2) -> 0
A12: 35936 | B12: =(Sheet1!B14-Sheet1!B12)/($A$4-$A$2) -> 0 | C12: =(Sheet1!C14-Sheet1!C12)/($A$4-$A$2) -> 0 | D12: =(Sheet1!D14-Sheet1!D12)/($A$4-$A$2) -> 0 | E12: =(Sheet1!E14-Sheet1!E12)/($A$4-$A$2) -> 0 | F12: =(Sheet1!F14-Sheet1!F12)/($A$4-$A$2) -> 0 | G12: =(Sheet1!G14-Sheet1!G12)/($A$4-$A$2) -> 0 | H12: =(Sheet1!H14-Sheet1!H12)/($A$4-$A$2) -> 0 | I12: =(Sheet1!I14-Sheet1!I12)/($A$4-$A$2) -> 0 | ... T12: =(Sheet1!T14-Sheet1!T12)/($A$4-$A$2) -> 0
A13: 35937 | B13: =(Sheet1!B15-Sheet1!B13)/($A$4-$A$2) -> 0 | C13: =(Sheet1!C15-Sheet1!C13)/($A$4-$A$2) -> 0 | D13: =(Sheet1!D15-Sheet1!D13)/($A$4-$A$2) -> 0 | E13: =(Sheet1!E15-Sheet1!E13)/($A$4-$A$2) -> 0 | F13: =(Sheet1!F15-Sheet1!F13)/($A$4-$A$2) -> 0 | G13: =(Sheet1!G15-Sheet1!G13)/($A$4-$A$2) -> 0 | H13: =(Sheet1!H15-Sheet1!H13)/($A$4-$A$2) -> 0 | I13: =(Sheet1!I15-Sheet1!I13)/($A$4-$A$2) -> 0 | ... T13: =(Sheet1!T15-Sheet1!T13)/($A$4-$A$2) -> 0
... A7195: 45975 | B7195: =(Sheet1!B7197-Sheet1!B7195)/($A$4-$A$2) -> -0.783011 | C7195: =(Sheet1!C7197-Sheet1!C7195)/($A$4-$A$2) -> -7.7408455 | D7195: =(Sheet1!D7197-Sheet1!D7195)/($A$4-$A$2) -> -2.013538 | E7195: =(Sheet1!E7197-Sheet1!E7195)/($A$4-$A$2) -> -1.9977645 | F7195: =(Sheet1!F7197-Sheet1!F7195)/($A$4-$A$2) -> -3.461548 | G7195: =(Sheet1!G7197-Sheet1!G7195)/($A$4-$A$2) -> -0.698848 | H7195: =(Sheet1!H7197-Sheet1!H7195)/($A$4-$A$2) -> -12.648811 | I7195: =(Sheet1!I7197-Sheet1!I7195)/($A$4-$A$2) -> -1.262819 | ... T7195: =(Sheet1!T7197-Sheet1!T7195)/($A$4-$A$2) -> -0.4754195

Sheet coverencia
B1: HOLD+Galaxis+EURO+Abszolút+Hozamú+Alapok+Alapja | C1: HOLD+Hozamkereső+Európai+Származtatott+Részvény+Befektetési+Alap | D1: HOLD+Kötvény+Befektetési+Alap | E1: HOLD+Közép-európai+Részvény+Befektetési+Alap | F1: HOLD+Nemzetközi+Részvény+Alapok+Alapja+A+sorozat | G1: HOLD+Orion+Abszolút+Hozamú+Származtatott+Befektetési+Alap+B+sorozat+EUR | H1: HOLD+Részvény+Befektetési+Alap+A+sorozat+HUF | I1: HOLD+Részvény+Befektetési+Alap+B+sorozat+EUR | J1: HOLD+Rövid+Futamidejű+Kötvény+Befektetési+Alap | K1: HOLD+Széf+USD+Abszolút+Hozamú+Befektetési+Alap | L1: HOLD+VM+Abszolút+Hozamú+Származtatott+Befektetési+Alap+C+sorozat | M1: HOLD+VM+EURO+Abszolút+Hozamú+Alapok+Alapja | N1: Palomar+Abszolút+Hozamú+Származtatott+Befektetési+Alap+A+sorozat+HUF | O1: Palomar+Abszolút+Hozamú+Származtatott+Befektetési+Alap+B+sorozat+EUR | P1: Palomar+Abszolút+Hozamú+Származtatott+Befektetési+Alap+C+sorozat+USD | Q1: Platina+Delta+Abszolút+Hozamú+Származtatott+Befektetési+Alap+E+sorozat+EUR | R1: Platina+Delta+Abszolút+Hozamú+Származtatott+Befektetési+Alap+X+sorozat+HUF | S1: Superposition+Abszolút+Hozamú+Származtatott+Befektetési+Alap+A+sorozat | T1: Superposition+Abszolút+Hozamú+Származtatott+Befektetési+Alap+D+sorozat+EUR
B2: =_xlfn.COVARIANCE.S(derivalt!B$2:B$7195,derivalt!$B$2:$B$7195) -> 0.00024244701 | C2: =_xlfn.COVARIANCE.S(derivalt!$B$2:$B$7195,derivalt!C$2:C$7195) -> 0.0017241571 | D2: =_xlfn.COVARIANCE.S(derivalt!$B$2:$B$7195,derivalt!D$2:D$7195) -> 0.00044136994 | E2: =_xlfn.COVARIANCE.S(derivalt!$B$2:$B$7195,derivalt!E$2:E$7195) -> 0.00044224983 | F2: =_xlfn.COVARIANCE.S(derivalt!$B$2:$B$7195,derivalt!F$2:F$7195) -> 0.00076138408 | G2: =_xlfn.COVARIANCE.S(derivalt!$B$2:$B$7195,derivalt!G$2:G$7195) -> 0.00015400415 | H2: =_xlfn.COVARIANCE.S(derivalt!$B$2:$B$7195,derivalt!H$2:H$7195) -> 0.0028062184 | I2: =_xlfn.COVARIANCE.S(derivalt!$B$2:$B$7195,derivalt!I$2:I$7195) -> 0.0002798069 | J2: =_xlfn.COVARIANCE.S(derivalt!$B$2:$B$7195,derivalt!J$2:J$7195) -> 0.00063419141 | ... T2: =_xlfn.COVARIANCE.S(derivalt!$B$2:$B$7195,derivalt!T$2:T$7195) -> 0.00010402987
B3: =_xlfn.COVARIANCE.S(derivalt!$C$2:$C$7195,derivalt!B$2:B$7195) -> 0.0017241571 | C3: =_xlfn.COVARIANCE.S(derivalt!$C$2:$C$7195,derivalt!C$2:C$7195) -> 0.026685972 | D3: =_xlfn.COVARIANCE.S(derivalt!$C$2:$C$7195,derivalt!D$2:D$7195) -> 0.0044020745 | E3: =_xlfn.COVARIANCE.S(derivalt!$C$2:$C$7195,derivalt!E$2:E$7195) -> 0.0045865769 | F3: =_xlfn.COVARIANCE.S(derivalt!$C$2:$C$7195,derivalt!F$2:F$7195) -> 0.0078881875 | G3: =_xlfn.COVARIANCE.S(derivalt!$C$2:$C$7195,derivalt!G$2:G$7195) -> 0.0015205722 | H3: =_xlfn.COVARIANCE.S(derivalt!$C$2:$C$7195,derivalt!H$2:H$7195) -> 0.028922682 | I3: =_xlfn.COVARIANCE.S(derivalt!$C$2:$C$7195,derivalt!I$2:I$7195) -> 0.0028443689 | ... T3: =_xlfn.COVARIANCE.S(derivalt!$C$2:$C$7195,derivalt!T$2:T$7195) -> 0.0010237141
B4: =_xlfn.COVARIANCE.S(derivalt!$D$2:$D$7195,derivalt!B$2:B$7195) -> 0.00044136994 | C4: =_xlfn.COVARIANCE.S(derivalt!$D$2:$D$7195,derivalt!C$2:C$7195) -> 0.0044020745 | D4: =_xlfn.COVARIANCE.S(derivalt!$D$2:$D$7195,derivalt!D$2:D$7195) -> 0.0012418012 | E4: =_xlfn.COVARIANCE.S(derivalt!$D$2:$D$7195,derivalt!E$2:E$7195) -> 0.0011297496 | F4: =_xlfn.COVARIANCE.S(derivalt!$D$2:$D$7195,derivalt!F$2:F$7195) -> 0.0019326588 | G4: =_xlfn.COVARIANCE.S(derivalt!$D$2:$D$7195,derivalt!G$2:G$7195) -> 0.00039341079 | H4: =_xlfn.COVARIANCE.S(derivalt!$D$2:$D$7195,derivalt!H$2:H$7195) -> 0.0072197797 | I4: =_xlfn.COVARIANCE.S(derivalt!$D$2:$D$7195,derivalt!I$2:I$7195) -> 0.00071195213 | ... T4: =_xlfn.COVARIANCE.S(derivalt!$D$2:$D$7195,derivalt!T$2:T$7195) -> 0.0002677888
B5: =_xlfn.COVARIANCE.S(derivalt!$E$2:$E$7195,derivalt!B$2:B$7195) -> 0.00044224983 | C5: =_xlfn.COVARIANCE.S(derivalt!$E$2:$E$7195,derivalt!C$2:C$7195) -> 0.0045865769 | D5: =_xlfn.COVARIANCE.S(derivalt!$E$2:$E$7195,derivalt!D$2:D$7195) -> 0.0011297496 | E5: =_xlfn.COVARIANCE.S(derivalt!$E$2:$E$7195,derivalt!E$2:E$7195) -> 0.0012567638 | F5: =_xlfn.COVARIANCE.S(derivalt!$E$2:$E$7195,derivalt!F$2:F$7195) -> 0.0019992602 | G5: =_xlfn.COVARIANCE.S(derivalt!$E$2:$E$7195,derivalt!G$2:G$7195) -> 0.00039558824 | H5: =_xlfn.COVARIANCE.S(derivalt!$E$2:$E$7195,derivalt!H$2:H$7195) -> 0.0073893948 | I5: =_xlfn.COVARIANCE.S(derivalt!$E$2:$E$7195,derivalt!I$2:I$7195) -> 0.00073238842 | ... T5: =_xlfn.COVARIANCE.S(derivalt!$E$2:$E$7195,derivalt!T$2:T$7195) -> 0.00026578863
B6: =_xlfn.COVARIANCE.S(derivalt!$F$2:$F$7195,derivalt!B$2:B$7195) -> 0.00076138408 | C6: =_xlfn.COVARIANCE.S(derivalt!$F$2:$F$7195,derivalt!C$2:C$7195) -> 0.0078881875 | D6: =_xlfn.COVARIANCE.S(derivalt!$F$2:$F$7195,derivalt!D$2:D$7195) -> 0.0019326588 | E6: =_xlfn.COVARIANCE.S(derivalt!$F$2:$F$7195,derivalt!E$2:E$7195) -> 0.0019992602 | F6: =_xlfn.COVARIANCE.S(derivalt!$F$2:$F$7195,derivalt!F$2:F$7195) -> 0.0041806452 | G6: =_xlfn.COVARIANCE.S(derivalt!$F$2:$F$7195,derivalt!G$2:G$7195) -> 0.00068267092 | H6: =_xlfn.COVARIANCE.S(derivalt!$F$2:$F$7195,derivalt!H$2:H$7195) -> 0.012622509 | I6: =_xlfn.COVARIANCE.S(derivalt!$F$2:$F$7195,derivalt!I$2:I$7195) -> 0.0012544495 | ... T6: =_xlfn.COVARIANCE.S(derivalt!$F$2:$F$7195,derivalt!T$2:T$7195) -> 0.00045811575
B7: =_xlfn.COVARIANCE.S(derivalt!$G$2:$G$7195,derivalt!B$2:B$7195) -> 0.00015400415 | C7: =_xlfn.COVARIANCE.S(derivalt!$G$2:$G$7195,derivalt!C$2:C$7195) -> 0.0015205722 | D7: =_xlfn.COVARIANCE.S(derivalt!$G$2:$G$7195,derivalt!D$2:D$7195) -> 0.00039341079 | E7: =_xlfn.COVARIANCE.S(derivalt!$G$2:$G$7195,derivalt!E$2:E$7195) -> 0.00039558824 | F7: =_xlfn.COVARIANCE.S(derivalt!$G$2:$G$7195,derivalt!F$2:F$7195) -> 0.00068267092 | G7: =_xlfn.COVARIANCE.S(derivalt!$G$2:$G$7195,derivalt!G$2:G$7195) -> 0.00020791466 | H7: =_xlfn.COVARIANCE.S(derivalt!$G$2:$G$7195,derivalt!H$2:H$7195) -> 0.0025077963 | I7: =_xlfn.COVARIANCE.S(derivalt!$G$2:$G$7195,derivalt!I$2:I$7195) -> 0.00025080233 | ... T7: =_xlfn.COVARIANCE.S(derivalt!$G$2:$G$7195,derivalt!T$2:T$7195) -> 9.3170257e-05
B8: =_xlfn.COVARIANCE.S(derivalt!$H$2:$H$7195,derivalt!B$2:B$7195) -> 0.0028062184 | C8: =_xlfn.COVARIANCE.S(derivalt!$H$2:$H$7195,derivalt!C$2:C$7195) -> 0.028922682 | D8: =_xlfn.COVARIANCE.S(derivalt!$H$2:$H$7195,derivalt!D$2:D$7195) -> 0.0072197797 | E8: =_xlfn.COVARIANCE.S(derivalt!$H$2:$H$7195,derivalt!E$2:E$7195) -> 0.0073893948 | F8: =_xlfn.COVARIANCE.S(derivalt!$H$2:$H$7195,derivalt!F$2:F$7195) -> 0.012622509 | G8: =_xlfn.COVARIANCE.S(derivalt!$H$2:$H$7195,derivalt!G$2:G$7195) -> 0.0025077963 | H8: =_xlfn.COVARIANCE.S(derivalt!$H$2:$H$7195,derivalt!H$2:H$7195) -> 0.046751149 | I8: =_xlfn.COVARIANCE.S(derivalt!$H$2:$H$7195,derivalt!I$2:I$7195) -> 0.0046313487 | ... T8: =_xlfn.COVARIANCE.S(derivalt!$H$2:$H$7195,derivalt!T$2:T$7195) -> 0.0016817976
B9: =_xlfn.COVARIANCE.S(derivalt!$I$2:$I$7195,derivalt!B$2:B$7195) -> 0.0002798069 | C9: =_xlfn.COVARIANCE.S(derivalt!$I$2:$I$7195,derivalt!C$2:C$7195) -> 0.0028443689 | D9: =_xlfn.COVARIANCE.S(derivalt!$I$2:$I$7195,derivalt!D$2:D$7195) -> 0.00071195213 | E9: =_xlfn.COVARIANCE.S(derivalt!$I$2:$I$7195,derivalt!E$2:E$7195) -> 0.00073238842 | F9: =_xlfn.COVARIANCE.S(derivalt!$I$2:$I$7195,derivalt!F$2:F$7195) -> 0.0012544495 | G9: =_xlfn.COVARIANCE.S(derivalt!$I$2:$I$7195,derivalt!G$2:G$7195) -> 0.00025080233 | H9: =_xlfn.COVARIANCE.S(derivalt!$I$2:$I$7195,derivalt!H$2:H$7195) -> 0.0046313487 | I9: =_xlfn.COVARIANCE.S(derivalt!$I$2:$I$7195,derivalt!I$2:I$7195) -> 0.00053245709 | ... T9: =_xlfn.COVARIANCE.S(derivalt!$I$2:$I$7195,derivalt!T$2:T$7195) -> 0.00016797004
B10: =_xlfn.COVARIANCE.S(derivalt!$J$2:$J$7195,derivalt!B$2:B$7195) -> 0.00063419141 | C10: =_xlfn.COVARIANCE.S(derivalt!$J$2:$J$7195,derivalt!C$2:C$7195) -> 0.0062889434 | D10: =_xlfn.COVARIANCE.S(derivalt!$J$2:$J$7195,derivalt!D$2:D$7195) -> 0.0016422992 | E10: =_xlfn.COVARIANCE.S(derivalt!$J$2:$J$7195,derivalt!E$2:E$7195) -> 0.001622276 | F10: =_xlfn.COVARIANCE.S(derivalt!$J$2:$J$7195,derivalt!F$2:F$7195) -> 0.0027973634 | G10: =_xlfn.COVARIANCE.S(derivalt!$J$2:$J$7195,derivalt!G$2:G$7195) -> 0.00056622011 | H10: =_xlfn.COVARIANCE.S(derivalt!$J$2:$J$7195,derivalt!H$2:H$7195) -> 0.010272683 | I10: =_xlfn.COVARIANCE.S(derivalt!$J$2:$J$7195,derivalt!I$2:I$7195) -> 0.0010243719 | ... T10: =_xlfn.COVARIANCE.S(derivalt!$J$2:$J$7195,derivalt!T$2:T$7195) -> 0.00038520098
B11: =_xlfn.COVARIANCE.S(derivalt!$K$2:$K$7195,derivalt!B$2:B$7195) -> 1.2679307e-06 | C11: =_xlfn.COVARIANCE.S(derivalt!$K$2:$K$7195,derivalt!C$2:C$7195) -> 1.2556936e-05 | D11: =_xlfn.COVARIANCE.S(derivalt!$K$2:$K$7195,derivalt!D$2:D$7195) -> 3.2566464e-06 | E11: =_xlfn.COVARIANCE.S(derivalt!$K$2:$K$7195,derivalt!E$2:E$7195) -> 3.2396704e-06 | F11: =_xlfn.COVARIANCE.S(derivalt!$K$2:$K$7195,derivalt!F$2:F$7195) -> 5.6075398e-06 | G11: =_xlfn.COVARIANCE.S(derivalt!$K$2:$K$7195,derivalt!G$2:G$7195) -> 1.1322596e-06 | H11: =_xlfn.COVARIANCE.S(derivalt!$K$2:$K$7195,derivalt!H$2:H$7195) -> 2.0525123e-05 | I11: =_xlfn.COVARIANCE.S(derivalt!$K$2:$K$7195,derivalt!I$2:I$7195) -> 2.0491618e-06 | ... T11: =_xlfn.COVARIANCE.S(derivalt!$K$2:$K$7195,derivalt!T$2:T$7195) -> 7.7019823e-07
B12: =_xlfn.COVARIANCE.S(derivalt!$L$2:$L$7195,derivalt!B$2:B$7195) -> 0.00015965739 | C12: =_xlfn.COVARIANCE.S(derivalt!$L$2:$L$7195,derivalt!C$2:C$7195) -> 0.0015812696 | D12: =_xlfn.COVARIANCE.S(derivalt!$L$2:$L$7195,derivalt!D$2:D$7195) -> 0.00041029357 | E12: =_xlfn.COVARIANCE.S(derivalt!$L$2:$L$7195,derivalt!E$2:E$7195) -> 0.00040890725 | F12: =_xlfn.COVARIANCE.S(derivalt!$L$2:$L$7195,derivalt!F$2:F$7195) -> 0.000707088 | G12: =_xlfn.COVARIANCE.S(derivalt!$L$2:$L$7195,derivalt!G$2:G$7195) -> 0.00014264918 | H12: =_xlfn.COVARIANCE.S(derivalt!$L$2:$L$7195,derivalt!H$2:H$7195) -> 0.0025878426 | I12: =_xlfn.COVARIANCE.S(derivalt!$L$2:$L$7195,derivalt!I$2:I$7195) -> 0.00025834497 | ... T12: =_xlfn.COVARIANCE.S(derivalt!$L$2:$L$7195,derivalt!T$2:T$7195) -> 9.7068036e-05
B13: =_xlfn.COVARIANCE.S(derivalt!$M$2:$M$7195,derivalt!B$2:B$7195) -> 0.0012295263 | C13: =_xlfn.COVARIANCE.S(derivalt!$M$2:$M$7195,derivalt!C$2:C$7195) -> 0.012217749 | D13: =_xlfn.COVARIANCE.S(derivalt!$M$2:$M$7195,derivalt!D$2:D$7195) -> 0.0031341042 | E13: =_xlfn.COVARIANCE.S(derivalt!$M$2:$M$7195,derivalt!E$2:E$7195) -> 0.0031236919 | F13: =_xlfn.COVARIANCE.S(derivalt!$M$2:$M$7195,derivalt!F$2:F$7195) -> 0.0054516634 | G13: =_xlfn.COVARIANCE.S(derivalt!$M$2:$M$7195,derivalt!G$2:G$7195) -> 0.0010954501 | H13: =_xlfn.COVARIANCE.S(derivalt!$M$2:$M$7195,derivalt!H$2:H$7195) -> 0.019815745 | I13: =_xlfn.COVARIANCE.S(derivalt!$M$2:$M$7195,derivalt!I$2:I$7195) -> 0.0019809375 | ... T13: =_xlfn.COVARIANCE.S(derivalt!$M$2:$M$7195,derivalt!T$2:T$7195) -> 0.00074453098
B14: =_xlfn.COVARIANCE.S(derivalt!$N$2:$N$7195,derivalt!B$2:B$7195) -> 0.00015973017 | C14: =_xlfn.COVARIANCE.S(derivalt!$N$2:$N$7195,derivalt!C$2:C$7195) -> 0.0015866754 | D14: =_xlfn.COVARIANCE.S(derivalt!$N$2:$N$7195,derivalt!D$2:D$7195) -> 0.0004093826 | E14: =_xlfn.COVARIANCE.S(derivalt!$N$2:$N$7195,derivalt!E$2:E$7195) -> 0.00040784969 | F14: =_xlfn.COVARIANCE.S(derivalt!$N$2:$N$7195,derivalt!F$2:F$7195) -> 0.00070737935 | G14: =_xlfn.COVARIANCE.S(derivalt!$N$2:$N$7195,derivalt!G$2:G$7195) -> 0.00014261816 | H14: =_xlfn.COVARIANCE.S(derivalt!$N$2:$N$7195,derivalt!H$2:H$7195) -> 0.0025824991 | I14: =_xlfn.COVARIANCE.S(derivalt!$N$2:$N$7195,derivalt!I$2:I$7195) -> 0.00025770424 | ... T14: =_xlfn.COVARIANCE.S(derivalt!$N$2:$N$7195,derivalt!T$2:T$7195) -> 9.7290825e-05
B15: =_xlfn.COVARIANCE.S(derivalt!$O$2:$O$7195,derivalt!B$2:B$7195) -> 0.00013053276 | C15: =_xlfn.COVARIANCE.S(derivalt!$O$2:$O$7195,derivalt!C$2:C$7195) -> 0.0012976999 | D15: =_xlfn.COVARIANCE.S(derivalt!$O$2:$O$7195,derivalt!D$2:D$7195) -> 0.00033452481 | E15: =_xlfn.COVARIANCE.S(derivalt!$O$2:$O$7195,derivalt!E$2:E$7195) -> 0.00033326817 | F15: =_xlfn.COVARIANCE.S(derivalt!$O$2:$O$7195,derivalt!F$2:F$7195) -> 0.0005783206 | G15: =_xlfn.COVARIANCE.S(derivalt!$O$2:$O$7195,derivalt!G$2:G$7195) -> 0.00011669429 | H15: =_xlfn.COVARIANCE.S(derivalt!$O$2:$O$7195,derivalt!H$2:H$7195) -> 0.0021098586 | I15: =_xlfn.COVARIANCE.S(derivalt!$O$2:$O$7195,derivalt!I$2:I$7195) -> 0.00021053817 | ... T15: =_xlfn.COVARIANCE.S(derivalt!$O$2:$O$7195,derivalt!T$2:T$7195) -> 7.9550423e-05
B16: =_xlfn.COVARIANCE.S(derivalt!$P$2:$P$7195,derivalt!B$2:B$7195) -> 0.00013994268 | C16: =_xlfn.COVARIANCE.S(derivalt!$P$2:$P$7195,derivalt!C$2:C$7195) -> 0.0013907977 | D16: =_xlfn.COVARIANCE.S(derivalt!$P$2:$P$7195,derivalt!D$2:D$7195) -> 0.0003586787 | E16: =_xlfn.COVARIANCE.S(derivalt!$P$2:$P$7195,derivalt!E$2:E$7195) -> 0.0003573103 | F16: =_xlfn.COVARIANCE.S(derivalt!$P$2:$P$7195,derivalt!F$2:F$7195) -> 0.00061970021 | G16: =_xlfn.COVARIANCE.S(derivalt!$P$2:$P$7195,derivalt!G$2:G$7195) -> 0.0001248915 | H16: =_xlfn.COVARIANCE.S(derivalt!$P$2:$P$7195,derivalt!H$2:H$7195) -> 0.0022621974 | I16: =_xlfn.COVARIANCE.S(derivalt!$P$2:$P$7195,derivalt!I$2:I$7195) -> 0.00022574168 | ... T16: =_xlfn.COVARIANCE.S(derivalt!$P$2:$P$7195,derivalt!T$2:T$7195) -> 8.5232078e-05
B17: =_xlfn.COVARIANCE.S(derivalt!$Q$2:$Q$7195,derivalt!B$2:B$7195) -> 0.00012746617 | C17: =_xlfn.COVARIANCE.S(derivalt!$Q$2:$Q$7195,derivalt!C$2:C$7195) -> 0.0012592135 | D17: =_xlfn.COVARIANCE.S(derivalt!$Q$2:$Q$7195,derivalt!D$2:D$7195) -> 0.00032641546 | E17: =_xlfn.COVARIANCE.S(derivalt!$Q$2:$Q$7195,derivalt!E$2:E$7195) -> 0.0003238358 | F17: =_xlfn.COVARIANCE.S(derivalt!$Q$2:$Q$7195,derivalt!F$2:F$7195) -> 0.00055014713 | G17: =_xlfn.COVARIANCE.S(derivalt!$Q$2:$Q$7195,derivalt!G$2:G$7195) -> 0.00011334922 | H17: =_xlfn.COVARIANCE.S(derivalt!$Q$2:$Q$7195,derivalt!H$2:H$7195) -> 0.0020545542 | I17: =_xlfn.COVARIANCE.S(derivalt!$Q$2:$Q$7195,derivalt!I$2:I$7195) -> 0.00020511654 | ... T17: =_xlfn.COVARIANCE.S(derivalt!$Q$2:$Q$7195,derivalt!T$2:T$7195) -> 7.6772628e-05
B18: =_xlfn.COVARIANCE.S(derivalt!$R$2:$R$7195,derivalt!B$2:B$7195) -> 0.0001305058 | C18: =_xlfn.COVARIANCE.S(derivalt!$R$2:$R$7195,derivalt!C$2:C$7195) -> 0.0012893536 | D18: =_xlfn.COVARIANCE.S(derivalt!$R$2:$R$7195,derivalt!D$2:D$7195) -> 0.00033421154 | E18: =_xlfn.COVARIANCE.S(derivalt!$R$2:$R$7195,derivalt!E$2:E$7195) -> 0.00033163295 | F18: =_xlfn.COVARIANCE.S(derivalt!$R$2:$R$7195,derivalt!F$2:F$7195) -> 0.00056361585 | G18: =_xlfn.COVARIANCE.S(derivalt!$R$2:$R$7195,derivalt!G$2:G$7195) -> 0.0001160654 | H18: =_xlfn.COVARIANCE.S(derivalt!$R$2:$R$7195,derivalt!H$2:H$7195) -> 0.0021038944 | I18: =_xlfn.COVARIANCE.S(derivalt!$R$2:$R$7195,derivalt!I$2:I$7195) -> 0.00021004132 | ... T18: =_xlfn.COVARIANCE.S(derivalt!$R$2:$R$7195,derivalt!T$2:T$7195) -> 7.8615081e-05
B19: =_xlfn.COVARIANCE.S(derivalt!$S$2:$S$7195,derivalt!B$2:B$7195) -> 0.0002192437 | C19: =_xlfn.COVARIANCE.S(derivalt!$S$2:$S$7195,derivalt!C$2:C$7195) -> 0.0021380463 | D19: =_xlfn.COVARIANCE.S(derivalt!$S$2:$S$7195,derivalt!D$2:D$7195) -> 0.00055985976 | E19: =_xlfn.COVARIANCE.S(derivalt!$S$2:$S$7195,derivalt!E$2:E$7195) -> 0.00055681741 | F19: =_xlfn.COVARIANCE.S(derivalt!$S$2:$S$7195,derivalt!F$2:F$7195) -> 0.00095813452 | G19: =_xlfn.COVARIANCE.S(derivalt!$S$2:$S$7195,derivalt!G$2:G$7195) -> 0.00019493023 | H19: =_xlfn.COVARIANCE.S(derivalt!$S$2:$S$7195,derivalt!H$2:H$7195) -> 0.0035265527 | I19: =_xlfn.COVARIANCE.S(derivalt!$S$2:$S$7195,derivalt!I$2:I$7195) -> 0.00035191894 | ... T19: =_xlfn.COVARIANCE.S(derivalt!$S$2:$S$7195,derivalt!T$2:T$7195) -> 0.00013187562
B20: =_xlfn.COVARIANCE.S(derivalt!$T$2:$T$7195,derivalt!B2:B7195) -> 0.00010402987 | C20: =_xlfn.COVARIANCE.S(derivalt!$T$2:$T$7195,derivalt!C2:C7195) -> 0.0010237141 | D20: =_xlfn.COVARIANCE.S(derivalt!$T$2:$T$7195,derivalt!D2:D7195) -> 0.0002677888 | E20: =_xlfn.COVARIANCE.S(derivalt!$T$2:$T$7195,derivalt!E2:E7195) -> 0.00026578863 | F20: =_xlfn.COVARIANCE.S(derivalt!$T$2:$T$7195,derivalt!F2:F7195) -> 0.00045811575 | G20: =_xlfn.COVARIANCE.S(derivalt!$T$2:$T$7195,derivalt!G2:G7195) -> 9.3170257e-05 | H20: =_xlfn.COVARIANCE.S(derivalt!$T$2:$T$7195,derivalt!H2:H7195) -> 0.0016817976 | I20: =_xlfn.COVARIANCE.S(derivalt!$T$2:$T$7195,derivalt!I2:I7195) -> 0.00016797004 | ... T20: =_xlfn.COVARIANCE.S(derivalt!$T$2:$T$7195,derivalt!T2:T7195) -> 0.00013319473
